Workbook

Sheet DATASHEET
B2: Variable name | D2: House building | E2: Nominal house price | F2: Nominal construction cost | G2: Transactions | H2: Private housing stock | I2: Interest rate | J2: House price (income) deflator | K2: Construction cost deflator
B3: Variable description | D3: Private enterprise starts, # homes | E3: Nominal house prices, £ | F3: Nominal construction cost, index | G3: Sales, # homes | H3: Owner-occupied + privated rented, # homes | I3: BOE official base rate, % | J3: Nominal disposable income / real disposable income, index | K3: GDP deflator, index
B4: Variable geography | D4: Great Britain | E4: United Kingdom | F4: Great Britain | G4: England & Wales | H4: Great Britain | I4: United Kingdom | J4: United Kingdom | K4: United Kingdom
B8: 1975 | C8: Q1 | D8: ='House building'!H8 -> 28800 | E8: ='Nominal house prices'!H8 -> 9179.4362 | F8: ='Nominal construction costs'!H8 -> 10.3 | G8: =Transactions!H8 -> 193500 | H8: ='Private housing stock'!Y8 -> 13573 | I8: ='Interest rate'!H8 -> 10.783333 | J8: ='House price (income) deflator'!H8 -> 13.222943 | K8: ='Construction cost deflator'!H8 -> 10.9778
C9: Q2 | D9: ='House building'!H9 -> 41600 | E9: ='Nominal house prices'!H9 -> 9423.1381 | F9: ='Nominal construction costs'!H9 -> 11.2 | G9: =Transactions!H9 -> 226500 | H9: ='Private housing stock'!Y9 -> 13587.284 | I9: ='Interest rate'!H9 -> 9.9615385 | J9: ='House price (income) deflator'!H9 -> 13.909269 | K9: ='Construction cost deflator'!H9 -> 11.7071
C10: Q3 | D10: ='House building'!H10 -> 41400 | E10: ='Nominal house prices'!H10 -> 9707.4569 | F10: ='Nominal construction costs'!H10 -> 11.7 | G10: =Transactions!H10 -> 236250 | H10: ='Private housing stock'!Y10 -> 13607.917 | I10: ='Interest rate'!H10 -> 10.706522 | J10: ='House price (income) deflator'!H10 -> 14.43728 | K10: ='Construction cost deflator'!H10 -> 12.2219
C11: Q4 | D11: ='House building'!H11 -> 37400 | E11: ='Nominal house prices'!H11 -> 9808.9993 | F11: ='Nominal construction costs'!H11 -> 11.5 | G11: =Transactions!H11 -> 224250 | H11: ='Private housing stock'!Y11 -> 13628.45 | I11: ='Interest rate'!H11 -> 11.730978 | J11: ='House price (income) deflator'!H11 -> 15.154198 | K11: ='Construction cost deflator'!H11 -> 12.7565
B12: 1976 | C12: Q1 | D12: ='House building'!H12 -> 37200 | E12: ='Nominal house prices'!H12 -> 10012.084 | F12: ='Nominal construction costs'!H12 -> 11.4 | G12: =Transactions!H12 -> 201750 | H12: ='Private housing stock'!Y12 -> 13647 | I12: ='Interest rate'!H12 -> 9.8681319 | J12: ='House price (income) deflator'!H12 -> 15.756414 | K12: ='Construction cost deflator'!H12 -> 13.1829
C13: Q2 | D13: ='House building'!H13 -> 46500 | E13: ='Nominal house prices'!H13 -> 10276.095 | F13: ='Nominal construction costs'!H13 -> 12.4 | G13: =Transactions!H13 -> 222750 | H13: ='Private housing stock'!Y13 -> 13672.025 | I13: ='Interest rate'!H13 -> 10.505495 | J13: ='House price (income) deflator'!H13 -> 16.154808 | K13: ='Construction cost deflator'!H13 -> 13.5525
C14: Q3 | D14: ='House building'!H14 -> 42800 | E14: ='Nominal house prices'!H14 -> 10519.796 | F14: ='Nominal construction costs'!H14 -> 12.8 | G14: =Transactions!H14 -> 237000 | H14: ='Private housing stock'!Y14 -> 13703.305 | I14: ='Interest rate'!H14 -> 11.793478 | J14: ='House price (income) deflator'!H14 -> 16.637217 | K14: ='Construction cost deflator'!H14 -> 13.8741
C15: Q4 | D15: ='House building'!H15 -> 28100 | E15: ='Nominal house prices'!H15 -> 10682.264 | F15: ='Nominal construction costs'!H15 -> 12.7 | G15: =Transactions!H15 -> 231000 | H15: ='Private housing stock'!Y15 -> 13732.097 | I15: ='Interest rate'!H15 -> 14.720109 | J15: ='House price (income) deflator'!H15 -> 17.573096 | K15: ='Construction cost deflator'!H15 -> 14.4219
B16: 1977 | C16: Q1 | D16: ='House building'!H16 -> 26200 | E16: ='Nominal house prices'!H16 -> 10763.498 | F16: ='Nominal construction costs'!H16 -> 12.3 | G16: =Transactions!H16 -> 196500 | H16: ='Private housing stock'!Y16 -> 13751 | I16: ='Interest rate'!H16 -> 12.325 | J16: ='House price (income) deflator'!H16 -> 18.243759 | K16: ='Construction cost deflator'!H16 -> 14.9647
C17: Q2 | D17: ='House building'!H17 -> 38100 | E17: ='Nominal house prices'!H17 -> 10925.966 | F17: ='Nominal construction costs'!H17 -> 13.5 | G17: =Transactions!H17 -> 225750 | H17: ='Private housing stock'!Y17 -> 13726.122 | I17: ='Interest rate'!H17 -> 8.4368132 | J17: ='House price (income) deflator'!H17 -> 18.934221 | K17: ='Construction cost deflator'!H17 -> 15.5529
C18: Q3 | D18: ='House building'!H18 -> 39100 | E18: ='Nominal house prices'!H18 -> 11250.902 | F18: ='Nominal construction costs'!H18 -> 14.1 | G18: =Transactions!H18 -> 249750 | H18: ='Private housing stock'!Y18 -> 13689.944 | I18: ='Interest rate'!H18 -> 7.2826087 | J18: ='House price (income) deflator'!H18 -> 19.311428 | K18: ='Construction cost deflator'!H18 -> 15.8767
C19: Q4 | D19: ='House building'!H19 -> 31400 | E19: ='Nominal house prices'!H19 -> 11596.146 | F19: ='Nominal construction costs'!H19 -> 14.1 | G19: =Transactions!H19 -> 257250 | H19: ='Private housing stock'!Y19 -> 13652.816 | I19: ='Interest rate'!H19 -> 5.875 | J19: ='House price (income) deflator'!H19 -> 19.647792 | K19: ='Construction cost deflator'!H19 -> 16.316
B20: 1978 | C20: Q1 | D20: ='House building'!H20 -> 30390 | E20: ='Nominal house prices'!H20 -> 11860.157 | F20: ='Nominal construction costs'!H20 -> 13.6 | G20: =Transactions!H20 -> 248250 | H20: ='Private housing stock'!Y20 -> 13623 | I20: ='Interest rate'!H20 -> 6.5444444 | J20: ='House price (income) deflator'!H20 -> 20.324324 | K20: ='Construction cost deflator'!H20 -> 16.9545
C21: Q2 | D21: ='House building'!H21 -> 46510 | E21: ='Nominal house prices'!H21 -> 12428.794 | F21: ='Nominal construction costs'!H21 -> 15.2 | G21: =Transactions!H21 -> 263250 | H21: ='Private housing stock'!Y21 -> 13650.432 | I21: ='Interest rate'!H21 -> 8.5027473 | J21: ='House price (income) deflator'!H21 -> 20.693377 | K21: ='Construction cost deflator'!H21 -> 17.4266
C22: Q3 | D22: ='House building'!H22 -> 41310 | E22: ='Nominal house prices'!H22 -> 13302.059 | F22: ='Nominal construction costs'!H22 -> 16.3 | G22: =Transactions!H22 -> 261750 | H22: ='Private housing stock'!Y22 -> 13692.416 | I22: ='Interest rate'!H22 -> 10 | J22: ='House price (income) deflator'!H22 -> 21.073563 | K22: ='Construction cost deflator'!H22 -> 17.6786
C23: Q4 | D23: ='House building'!H23 -> 39100 | E23: ='Nominal house prices'!H23 -> 14236.25 | F23: ='Nominal construction costs'!H23 -> 16.6 | G23: =Transactions!H23 -> 250500 | H23: ='Private housing stock'!Y23 -> 13729.705 | I23: ='Interest rate'!H23 -> 11.440217 | J23: ='House price (income) deflator'!H23 -> 21.77632 | K23: ='Construction cost deflator'!H23 -> 18.1534
B24: 1979 | C24: Q1 | D24: ='House building'!H24 -> 23320 | E24: ='Nominal house prices'!H24 -> 14987.664 | F24: ='Nominal construction costs'!H24 -> 16.2 | G24: =Transactions!H24 -> 229500 | H24: ='Private housing stock'!Y24 -> 13765 | I24: ='Interest rate'!H24 -> 13.022222 | J24: ='House price (income) deflator'!H24 -> 22.495944 | K24: ='Construction cost deflator'!H24 -> 18.8287
C25: Q2 | D25: ='House building'!H25 -> 40050 | E25: ='Nominal house prices'!H25 -> 16145.247 | F25: ='Nominal construction costs'!H25 -> 18.2 | G25: =Transactions!H25 -> 235500 | H25: ='Private housing stock'!Y25 -> 13787.671 | I25: ='Interest rate'!H25 -> 12.43956 | J25: ='House price (income) deflator'!H25 -> 22.975937 | K25: ='Construction cost deflator'!H25 -> 19.2827
C26: Q3 | D26: ='House building'!H26 -> 41250 | E26: ='Nominal house prices'!H26 -> 17384.065 | F26: ='Nominal construction costs'!H26 -> 20.1 | G26: =Transactions!H26 -> 258750 | H26: ='Private housing stock'!Y26 -> 13826.605 | I26: ='Interest rate'!H26 -> 14 | J26: ='House price (income) deflator'!H26 -> 24.540922 | K26: ='Construction cost deflator'!H26 -> 20.7477
C27: Q4 | D27: ='House building'!H27 -> 39390 | E27: ='Nominal house prices'!H27 -> 18541.649 | F27: ='Nominal construction costs'!H27 -> 20.6 | G27: =Transactions!H27 -> 255750 | H27: ='Private housing stock'!Y27 -> 13866.707 | I27: ='Interest rate'!H27 -> 15.532609 | J27: ='House price (income) deflator'!H27 -> 25.612205 | K27: ='Construction cost deflator'!H27 -> 21.6294
B28: 1980 | C28: Q1 | D28: ='House building'!H28 -> 24530 | E28: ='Nominal house prices'!H28 -> 19272.754 | F28: ='Nominal construction costs'!H28 -> 20.1 | G28: =Transactions!H28 -> 234000 | H28: ='Private housing stock'!Y28 -> 13905 | I28: ='Interest rate'!H28 -> 17 | J28: ='House price (income) deflator'!H28 -> 26.727327 | K28: ='Construction cost deflator'!H28 -> 22.724
C29: Q2 | D29: ='House building'!H29 -> 29440 | E29: ='Nominal house prices'!H29 -> 20044.477 | F29: ='Nominal construction costs'!H29 -> 23 | G29: =Transactions!H29 -> 246000 | H29: ='Private housing stock'!Y29 -> 13935.785 | I29: ='Interest rate'!H29 -> 17 | J29: ='House price (income) deflator'!H29 -> 27.671739 | K29: ='Construction cost deflator'!H29 -> 23.7775
C30: Q3 | D30: ='House building'!H30 -> 23370 | E30: ='Nominal house prices'!H30 -> 20856.816 | F30: ='Nominal construction costs'!H30 -> 24.5 | G30: =Transactions!H30 -> 231000 | H30: ='Private housing stock'!Y30 -> 13972.731 | I30: ='Interest rate'!H30 -> 16.021739 | J30: ='House price (income) deflator'!H30 -> 28.323628 | K30: ='Construction cost deflator'!H30 -> 24.6711
C31: Q4 | D31: ='House building'!H31 -> 20670 | E31: ='Nominal house prices'!H31 -> 20897.433 | F31: ='Nominal construction costs'!H31 -> 24.5 | G31: =Transactions!H31 -> 239250 | H31: ='Private housing stock'!Y31 -> 14002.06 | I31: ='Interest rate'!H31 -> 15.195652 | J31: ='House price (income) deflator'!H31 -> 29.568832 | K31: ='Construction cost deflator'!H31 -> 25.7582
B32: 1981 | C32: Q1 | D32: ='House building'!H32 -> 26290 | E32: ='Nominal house prices'!H32 -> 20938.05 | F32: ='Nominal construction costs'!H32 -> 23.1 | G32: =Transactions!H32 -> 216000 | H32: ='Private housing stock'!Y32 -> 14028 | I32: ='Interest rate'!H32 -> 13.533333 | J32: ='House price (income) deflator'!H32 -> 30.442952 | K32: ='Construction cost deflator'!H32 -> 26.4908
C33: Q2 | D33: ='House building'!H33 -> 32240 | E33: ='Nominal house prices'!H33 -> 21506.688 | F33: ='Nominal construction costs'!H33 -> 25.3 | G33: =Transactions!H33 -> 246000 | H33: ='Private housing stock'!Y33 -> 14072.757 | I33: ='Interest rate'!H33 -> 12 | J33: ='House price (income) deflator'!H33 -> 31.260893 | K33: ='Construction cost deflator'!H33 -> 26.9733
C34: Q3 | D34: ='House building'!H34 -> 32080 | E34: ='Nominal house prices'!H34 -> 21851.932 | F34: ='Nominal construction costs'!H34 -> 25.5 | G34: =Transactions!H34 -> 263250 | H34: ='Private housing stock'!Y34 -> 14127.643 | I34: ='Interest rate'!H34 -> 12.505326 | J34: ='House price (income) deflator'!H34 -> 31.966598 | K34: ='Construction cost deflator'!H34 -> 27.4242
C35: Q4 | D35: ='House building'!H35 -> 24520 | E35: ='Nominal house prices'!H35 -> 21425.454 | F35: ='Nominal construction costs'!H35 -> 24.5 | G35: =Transactions!H35 -> 288000 | H35: ='Private housing stock'!Y35 -> 14182.257 | I35: ='Interest rate'!H35 -> 14.599022 | J35: ='House price (income) deflator'!H35 -> 33.059927 | K35: ='Construction cost deflator'!H35 -> 28.2612
B36: 1982 | C36: Q1 | D36: ='House building'!H36 -> 31770 | E36: ='Nominal house prices'!H36 -> 20897.433 | F36: ='Nominal construction costs'!H36 -> 23.2 | G36: =Transactions!H36 -> 240000 | H36: ='Private housing stock'!Y36 -> 14224 | I36: ='Interest rate'!H36 -> 13.795 | J36: ='House price (income) deflator'!H36 -> 33.999461 | K36: ='Construction cost deflator'!H36 -> 28.956
C37: Q2 | D37: ='House building'!H37 -> 38120 | E37: ='Nominal house prices'!H37 -> 21811.315 | F37: ='Nominal construction costs'!H37 -> 25.2 | G37: =Transactions!H37 -> 276000 | H37: ='Private housing stock'!Y37 -> 14299.778 | I37: ='Interest rate'!H37 -> 13.021978 | J37: ='House price (income) deflator'!H37 -> 34.443782 | K37: ='Construction cost deflator'!H37 -> 29.2297
C38: Q3 | D38: ='House building'!H38 -> 38000 | E38: ='Nominal house prices'!H38 -> 22359.644 | F38: ='Nominal construction costs'!H38 -> 25.3 | G38: =Transactions!H38 -> 318000 | H38: ='Private housing stock'!Y38 -> 14390.702 | I38: ='Interest rate'!H38 -> 11.364239 | J38: ='House price (income) deflator'!H38 -> 34.840135 | K38: ='Construction cost deflator'!H38 -> 29.6918
C39: Q4 | D39: ='House building'!H39 -> 32140 | E39: ='Nominal house prices'!H39 -> 22684.58 | F39: ='Nominal construction costs'!H39 -> 24.8 | G39: =Transactions!H39 -> 321750 | H39: ='Private housing stock'!Y39 -> 14481.34 | I39: ='Interest rate'!H39 -> 9.701413 | J39: ='House price (income) deflator'!H39 -> 35.671708 | K39: ='Construction cost deflator'!H39 -> 30.3211
B40: 1983 | C40: Q1 | D40: ='House building'!H40 -> 39890 | E40: ='Nominal house prices'!H40 -> 23354.76 | F40: ='Nominal construction costs'!H40 -> 25.6 | G40: =Transactions!H40 -> 302250 | H40: ='Private housing stock'!Y40 -> 14558 | I40: ='Interest rate'!H40 -> 10.794667 | J40: ='House price (income) deflator'!H40 -> 36.393889 | K40: ='Construction cost deflator'!H40 -> 30.8562
C41: Q2 | D41: ='House building'!H41 -> 47850 | E41: ='Nominal house prices'!H41 -> 24167.1 | F41: ='Nominal construction costs'!H41 -> 26.2 | G41: =Transactions!H41 -> 308250 | H41: ='Private housing stock'!Y41 -> 14629.413 | I41: ='Interest rate'!H41 -> 10.032527 | J41: ='House price (income) deflator'!H41 -> 36.432132 | K41: ='Construction cost deflator'!H41 -> 30.9348
C42: Q3 | D42: ='House building'!H42 -> 43730 | E42: ='Nominal house prices'!H42 -> 25182.524 | F42: ='Nominal construction costs'!H42 -> 26.9 | G42: =Transactions!H42 -> 323250 | H42: ='Private housing stock'!Y42 -> 14715.077 | I42: ='Interest rate'!H42 -> 9.5586957 | J42: ='House price (income) deflator'!H42 -> 37.314785 | K42: ='Construction cost deflator'!H42 -> 31.3756
C43: Q4 | D43: ='House building'!H43 -> 37780 | E43: ='Nominal house prices'!H43 -> 25385.609 | F43: ='Nominal construction costs'!H43 -> 27.3 | G43: =Transactions!H43 -> 318000 | H43: ='Private housing stock'!Y43 -> 14793.364 | I43: ='Interest rate'!H43 -> 9.0708696 | J43: ='House price (income) deflator'!H43 -> 37.618284 | K43: ='Construction cost deflator'!H43 -> 31.945
B44: 1984 | C44: Q1 | D44: ='House building'!H44 -> 37090 | E44: ='Nominal house prices'!H44 -> 25588.694 | F44: ='Nominal construction costs'!H44 -> 27.8 | G44: =Transactions!H44 -> 318000 | H44: ='Private housing stock'!Y44 -> 14861 | I44: ='Interest rate'!H44 -> 8.9418681 | J44: ='House price (income) deflator'!H44 -> 38.155344 | K44: ='Construction cost deflator'!H44 -> 32.0195
...

Sheet House building
D3: Cat 1 | E3: Cat 2 | F3: Cat 3 | G3: Cat4 | H3: Updated | I3: Previous | J3: Difference
B4: Notes 1 | D4: [Geoff Meen] | E4: House building, UK: Permanent dwellings started & completed by country [ONS] | F4: House building, UK: Permanent dwellings started & completed by country [ONS] | G4: House building, UK: Permanent dwellings started & completed by country [ONS] | H4: Sum cats 1-4
B5: Notes 2 | E5: Private enterprise starts GB | F5: Private enterprise starts GB | G5: Private enterprise starts GB
B6: Link | D6: N/A | E6: https://www.ons.gov.uk/peoplepopulationandcommunity/housing/datasets/ukhousebuildingpermanentdwellingsstartedandcompleted | F6: https://www.ons.gov.uk/peoplepopulationandcommunity/housing/datasets/ukhousebuildingpermanentdwellingsstartedandcompleted | G6: https://www.ons.gov.uk/peoplepopulationandcommunity/housing/datasets/ukhousebuildingpermanentdwellingsstartedandcompleted
B7: Table | D7: N/A | E7: 1b | F7: 1c | G7: 1d
B8: 1975 | C8: Q1 | D8: 28800 | H8: =SUM(D8:G8) -> 28800 | I8: 28800 | J8: =H8-I8 -> 0
C9: Q2 | D9: 41600 | H9: =SUM(D9:G9) -> 41600 | I9: 41600 | J9: =H9-I9 -> 0
C10: Q3 | D10: 41400 | H10: =SUM(D10:G10) -> 41400 | I10: 41400 | J10: =H10-I10 -> 0
C11: Q4 | D11: 37400 | H11: =SUM(D11:G11) -> 37400 | I11: 37400 | J11: =H11-I11 -> 0
B12: 1976 | C12: Q1 | D12: 37200 | H12: =SUM(D12:G12) -> 37200 | I12: 37200 | J12: =H12-I12 -> 0
C13: Q2 | D13: 46500 | H13: =SUM(D13:G13) -> 46500 | I13: 46500 | J13: =H13-I13 -> 0
C14: Q3 | D14: 42800 | H14: =SUM(D14:G14) -> 42800 | I14: 42800 | J14: =H14-I14 -> 0
C15: Q4 | D15: 28100 | H15: =SUM(D15:G15) -> 28100 | I15: 28100 | J15: =H15-I15 -> 0
B16: 1977 | C16: Q1 | D16: 26200 | H16: =SUM(D16:G16) -> 26200 | I16: 26200 | J16: =H16-I16 -> 0
C17: Q2 | D17: 38100 | H17: =SUM(D17:G17) -> 38100 | I17: 38100 | J17: =H17-I17 -> 0
C18: Q3 | D18: 39100 | H18: =SUM(D18:G18) -> 39100 | I18: 39100 | J18: =H18-I18 -> 0
C19: Q4 | D19: 31400 | H19: =SUM(D19:G19) -> 31400 | I19: 31400 | J19: =H19-I19 -> 0
B20: 1978 | C20: Q1 | E20: 25880 | F20: 1490 | G20: 3020 | H20: =SUM(D20:G20) -> 30390 | I20: 30390 | J20: =H20-I20 -> 0
C21: Q2 | E21: 39760 | F21: 2110 | G21: 4640 | H21: =SUM(D21:G21) -> 46510 | I21: 46510 | J21: =H21-I21 -> 0
C22: Q3 | E22: 34490 | F22: 1780 | G22: 5040 | H22: =SUM(D22:G22) -> 41310 | I22: 41310 | J22: =H22-I22 -> 0
C23: Q4 | E23: 33450 | F23: 1790 | G23: 3860 | H23: =SUM(D23:G23) -> 39100 | I23: 39100 | J23: =H23-I23 -> 0
B24: 1979 | C24: Q1 | E24: 19060 | F24: 1460 | G24: 2800 | H24: =SUM(D24:G24) -> 23320 | I24: 23320 | J24: =H24-I24 -> 0
C25: Q2 | E25: 33300 | F25: 2100 | G25: 4650 | H25: =SUM(D25:G25) -> 40050 | I25: 40050 | J25: =H25-I25 -> 0
C26: Q3 | E26: 34260 | F26: 2550 | G26: 4440 | H26: =SUM(D26:G26) -> 41250 | I26: 41250 | J26: =H26-I26 -> 0
C27: Q4 | E27: 34510 | F27: 1470 | G27: 3410 | H27: =SUM(D27:G27) -> 39390 | I27: 39390 | J27: =H27-I27 -> 0
B28: 1980 | C28: Q1 | E28: 20470 | F28: 1300 | G28: 2760 | H28: =SUM(D28:G28) -> 24530 | I28: 24540 | J28: =H28-I28 -> -10
C29: Q2 | E29: 25210 | F29: 1480 | G29: 2750 | H29: =SUM(D29:G29) -> 29440 | I29: 29450 | J29: =H29-I29 -> -10
C30: Q3 | E30: 20120 | F30: 1030 | G30: 2220 | H30: =SUM(D30:G30) -> 23370 | I30: 23390 | J30: =H30-I30 -> -20
C31: Q4 | E31: 17500 | F31: 1220 | G31: 1950 | H31: =SUM(D31:G31) -> 20670 | I31: 20630 | J31: =H31-I31 -> 40
B32: 1981 | C32: Q1 | E32: 22790 | F32: 830 | G32: 2670 | H32: =SUM(D32:G32) -> 26290 | I32: 26290 | J32: =H32-I32 -> 0
C33: Q2 | E33: 27720 | F33: 1330 | G33: 3190 | H33: =SUM(D33:G33) -> 32240 | I33: 32280 | J33: =H33-I33 -> -40
C34: Q3 | E34: 27830 | F34: 1340 | G34: 2910 | H34: =SUM(D34:G34) -> 32080 | I34: 32040 | J34: =H34-I34 -> 40
C35: Q4 | E35: 21270 | F35: 990 | G35: 2260 | H35: =SUM(D35:G35) -> 24520 | I35: 24510 | J35: =H35-I35 -> 10
B36: 1982 | C36: Q1 | E36: 27730 | F36: 980 | G36: 3060 | H36: =SUM(D36:G36) -> 31770 | I36: 31730 | J36: =H36-I36 -> 40
C37: Q2 | E37: 33340 | F37: 1420 | G37: 3360 | H37: =SUM(D37:G37) -> 38120 | I37: 38050 | J37: =H37-I37 -> 70
C38: Q3 | E38: 33340 | F38: 1650 | G38: 3010 | H38: =SUM(D38:G38) -> 38000 | I38: 38010 | J38: =H38-I38 -> -10
C39: Q4 | E39: 28050 | F39: 1390 | G39: 2700 | H39: =SUM(D39:G39) -> 32140 | I39: 32260 | J39: =H39-I39 -> -120
B40: 1983 | C40: Q1 | E40: 34450 | F40: 1720 | G40: 3720 | H40: =SUM(D40:G40) -> 39890 | I40: 39920 | J40: =H40-I40 -> -30
C41: Q2 | E41: 41890 | F41: 1730 | G41: 4230 | H41: =SUM(D41:G41) -> 47850 | I41: 47810 | J41: =H41-I41 -> 40
C42: Q3 | E42: 38600 | F42: 1450 | G42: 3680 | H42: =SUM(D42:G42) -> 43730 | I42: 43830 | J42: =H42-I42 -> -100
...

Sheet Nominal house prices
D3: Cat 1 | E3: Cat 2 | F3: Cat 3 | G3: Cat4 | H3: Updated | I3: Previous | J3: Difference | L3: Raw data download processing..
B4: Notes 1 | D4: House Price Index [ONS, Land Registry] | H4: Cat 1
B5: Notes 2 | D5: Nominal house prices, UK
B6: Link | D6: UK House Price Index: data downloads September 2022 - GOV.UK (www.gov.uk)
B7: Table | D7: Average price, extract UK data
B8: 1975 | C8: Q1 | D8: 9179.4362 | H8: =SUM(D8:G8) -> 9179.4362 | I8: 9179.4362 | J8: =H8-I8 -> 0 | L8: 1975 | M8: January | N8: 9179.4362
C9: Q2 | D9: 9423.1381 | H9: =SUM(D9:G9) -> 9423.1381 | I9: 9423.1381 | J9: =H9-I9 -> 0 | L9: 1975 | M9: February | N9: 9179.4362
C10: Q3 | D10: 9707.4569 | H10: =SUM(D10:G10) -> 9707.4569 | I10: 9707.4569 | J10: =H10-I10 -> 0 | L10: 1975 | M10: March | N10: 9179.4362 | O10: =AVERAGE(N8:N10) -> 9179.4362
C11: Q4 | D11: 9808.9993 | H11: =SUM(D11:G11) -> 9808.9993 | I11: 9808.9993 | J11: =H11-I11 -> 0 | L11: 1975 | M11: April | N11: 9423.1381 | O11: =AVERAGE(N9:N11) -> 9260.6702
B12: 1976 | C12: Q1 | D12: 10012.084 | H12: =SUM(D12:G12) -> 10012.084 | I12: 10012.084 | J12: =H12-I12 -> 0 | L12: 1975 | M12: May | N12: 9423.1381 | O12: =AVERAGE(N10:N12) -> 9341.9041
C13: Q2 | D13: 10276.095 | H13: =SUM(D13:G13) -> 10276.095 | I13: 10276.095 | J13: =H13-I13 -> 0 | L13: 1975 | M13: June | N13: 9423.1381 | O13: =AVERAGE(N11:N13) -> 9423.1381
C14: Q3 | D14: 10519.796 | H14: =SUM(D14:G14) -> 10519.796 | I14: 10519.796 | J14: =H14-I14 -> 0 | L14: 1975 | M14: July | N14: 9707.4569 | O14: =AVERAGE(N12:N14) -> 9517.911
C15: Q4 | D15: 10682.264 | H15: =SUM(D15:G15) -> 10682.264 | I15: 10682.264 | J15: =H15-I15 -> 0 | L15: 1975 | M15: August | N15: 9707.4569 | O15: =AVERAGE(N13:N15) -> 9612.684
B16: 1977 | C16: Q1 | D16: 10763.498 | H16: =SUM(D16:G16) -> 10763.498 | I16: 10763.498 | J16: =H16-I16 -> 0 | L16: 1975 | M16: September | N16: 9707.4569 | O16: =AVERAGE(N14:N16) -> 9707.4569
C17: Q2 | D17: 10925.966 | H17: =SUM(D17:G17) -> 10925.966 | I17: 10925.966 | J17: =H17-I17 -> 0 | L17: 1975 | M17: October | N17: 9808.9993 | O17: =AVERAGE(N15:N17) -> 9741.3044
C18: Q3 | D18: 11250.902 | H18: =SUM(D18:G18) -> 11250.902 | I18: 11250.902 | J18: =H18-I18 -> 0 | L18: 1975 | M18: November | N18: 9808.9993 | O18: =AVERAGE(N16:N18) -> 9775.1519
C19: Q4 | D19: 11596.146 | H19: =SUM(D19:G19) -> 11596.146 | I19: 11596.146 | J19: =H19-I19 -> 0 | L19: 1975 | M19: December | N19: 9808.9993 | O19: =AVERAGE(N17:N19) -> 9808.9993
B20: 1978 | C20: Q1 | D20: 11860.157 | H20: =SUM(D20:G20) -> 11860.157 | I20: 11860.157 | J20: =H20-I20 -> 0 | L20: 1976 | M20: January | N20: 10012.084 | O20: =AVERAGE(N18:N20) -> 9876.6943
C21: Q2 | D21: 12428.794 | H21: =SUM(D21:G21) -> 12428.794 | I21: 12428.794 | J21: =H21-I21 -> 0 | L21: 1976 | M21: February | N21: 10012.084 | O21: =AVERAGE(N19:N21) -> 9944.3892
C22: Q3 | D22: 13302.059 | H22: =SUM(D22:G22) -> 13302.059 | I22: 13302.059 | J22: =H22-I22 -> 0 | L22: 1976 | M22: March | N22: 10012.084 | O22: =AVERAGE(N20:N22) -> 10012.084
C23: Q4 | D23: 14236.25 | H23: =SUM(D23:G23) -> 14236.25 | I23: 14236.25 | J23: =H23-I23 -> 0 | L23: 1976 | M23: April | N23: 10276.095 | O23: =AVERAGE(N21:N23) -> 10100.088
B24: 1979 | C24: Q1 | D24: 14987.664 | H24: =SUM(D24:G24) -> 14987.664 | I24: 14987.664 | J24: =H24-I24 -> 0 | L24: 1976 | M24: May | N24: 10276.095 | O24: =AVERAGE(N22:N24) -> 10188.091
C25: Q2 | D25: 16145.247 | H25: =SUM(D25:G25) -> 16145.247 | I25: 16145.247 | J25: =H25-I25 -> 0 | L25: 1976 | M25: June | N25: 10276.095 | O25: =AVERAGE(N23:N25) -> 10276.095
C26: Q3 | D26: 17384.065 | H26: =SUM(D26:G26) -> 17384.065 | I26: 17384.065 | J26: =H26-I26 -> 0 | L26: 1976 | M26: July | N26: 10519.796 | O26: =AVERAGE(N24:N26) -> 10357.328
C27: Q4 | D27: 18541.649 | H27: =SUM(D27:G27) -> 18541.649 | I27: 18541.649 | J27: =H27-I27 -> 0 | L27: 1976 | M27: August | N27: 10519.796 | O27: =AVERAGE(N25:N27) -> 10438.562
B28: 1980 | C28: Q1 | D28: 19272.754 | H28: =SUM(D28:G28) -> 19272.754 | I28: 19272.754 | J28: =H28-I28 -> 0 | L28: 1976 | M28: September | N28: 10519.796 | O28: =AVERAGE(N26:N28) -> 10519.796
C29: Q2 | D29: 20044.477 | H29: =SUM(D29:G29) -> 20044.477 | I29: 20044.477 | J29: =H29-I29 -> 0 | L29: 1976 | M29: October | N29: 10682.264 | O29: =AVERAGE(N27:N29) -> 10573.952
C30: Q3 | D30: 20856.816 | H30: =SUM(D30:G30) -> 20856.816 | I30: 20856.816 | J30: =H30-I30 -> 0 | L30: 1976 | M30: November | N30: 10682.264 | O30: =AVERAGE(N28:N30) -> 10628.108
C31: Q4 | D31: 20897.433 | H31: =SUM(D31:G31) -> 20897.433 | I31: 20897.433 | J31: =H31-I31 -> 0 | L31: 1976 | M31: December | N31: 10682.264 | O31: =AVERAGE(N29:N31) -> 10682.264
B32: 1981 | C32: Q1 | D32: 20938.05 | H32: =SUM(D32:G32) -> 20938.05 | I32: 20938.05 | J32: =H32-I32 -> 0 | L32: 1977 | M32: January | N32: 10763.498 | O32: =AVERAGE(N30:N32) -> 10709.342
C33: Q2 | D33: 21506.688 | H33: =SUM(D33:G33) -> 21506.688 | I33: 21506.688 | J33: =H33-I33 -> 0 | L33: 1977 | M33: February | N33: 10763.498 | O33: =AVERAGE(N31:N33) -> 10736.42
C34: Q3 | D34: 21851.932 | H34: =SUM(D34:G34) -> 21851.932 | I34: 21851.932 | J34: =H34-I34 -> 0 | L34: 1977 | M34: March | N34: 10763.498 | O34: =AVERAGE(N32:N34) -> 10763.498
C35: Q4 | D35: 21425.454 | H35: =SUM(D35:G35) -> 21425.454 | I35: 21425.454 | J35: =H35-I35 -> 0 | L35: 1977 | M35: April | N35: 10925.966 | O35: =AVERAGE(N33:N35) -> 10817.654
B36: 1982 | C36: Q1 | D36: 20897.433 | H36: =SUM(D36:G36) -> 20897.433 | I36: 20897.433 | J36: =H36-I36 -> 0 | L36: 1977 | M36: May | N36: 10925.966 | O36: =AVERAGE(N34:N36) -> 10871.81
C37: Q2 | D37: 21811.315 | H37: =SUM(D37:G37) -> 21811.315 | I37: 21811.315 | J37: =H37-I37 -> 0 | L37: 1977 | M37: June | N37: 10925.966 | O37: =AVERAGE(N35:N37) -> 10925.966
C38: Q3 | D38: 22359.644 | H38: =SUM(D38:G38) -> 22359.644 | I38: 22359.644 | J38: =H38-I38 -> 0 | L38: 1977 | M38: July | N38: 11250.902 | O38: =AVERAGE(N36:N38) -> 11034.278
C39: Q4 | D39: 22684.58 | H39: =SUM(D39:G39) -> 22684.58 | I39: 22684.58 | J39: =H39-I39 -> 0 | L39: 1977 | M39: August | N39: 11250.902 | O39: =AVERAGE(N37:N39) -> 11142.59
B40: 1983 | C40: Q1 | D40: 23354.76 | H40: =SUM(D40:G40) -> 23354.76 | I40: 23354.76 | J40: =H40-I40 -> 0 | L40: 1977 | M40: September | N40: 11250.902 | O40: =AVERAGE(N38:N40) -> 11250.902
C41: Q2 | D41: 24167.1 | H41: =SUM(D41:G41) -> 24167.1 | I41: 24167.1 | J41: =H41-I41 -> 0 | L41: 1977 | M41: October | N41: 11596.146 | O41: =AVERAGE(N39:N41) -> 11365.983
C42: Q3 | D42: 25182.524 | H42: =SUM(D42:G42) -> 25182.524 | I42: 25182.524 | J42: =H42-I42 -> 0 | L42: 1977 | M42: November | N42: 11596.146 | O42: =AVERAGE(N40:N42) -> 11481.065
...

Sheet Nominal construction costs
D3: Cat 1 | E3: Cat 2 | F3: Cat 3 | G3: Cat4 | H3: Updated | I3: Previous | J3: Difference | L3: Raw data download processing..
B4: Notes 1 | D4: BIS Quarterly construction price and cost indices: July to September 2014 [BIS] | E4: Construction output price indices [ONS] | H4: See formula in cells; cat 2 series rebased to match cat 1 series
B5: Notes 2 | D5: Output price index for new construction, private housing, GB | E5: New work output prices, housing, GB
B6: Link | D6: BIS quarterly construction price and cost indices: July to September 2014 - GOV.UK (www.gov.uk) | E6: Construction output price indices - Office for National Statistics
B7: Table | D7: Table 1 tab | E7: New work tab
B8: 1975 | C8: Q1 | D8: 10.3 | H8: =IF(D8>0,D8,D$164*E8/100) -> 10.3 | I8: 10.3 | J8: =H8-I8 -> 0 | L8: 2014 | M8: January | N8: 100.6
C9: Q2 | D9: 11.2 | H9: =IF(D9>0,D9,D$164*E9/100) -> 11.2 | I9: 11.2 | J9: =H9-I9 -> 0 | L9: 2014 | M9: February | N9: 99.9
C10: Q3 | D10: 11.7 | H10: =IF(D10>0,D10,D$164*E10/100) -> 11.7 | I10: 11.7 | J10: =H10-I10 -> 0 | L10: 2014 | M10: March | N10: 99.4 | O10: =AVERAGE(N8:N10) -> 99.966667
C11: Q4 | D11: 11.5 | H11: =IF(D11>0,D11,D$164*E11/100) -> 11.5 | I11: 11.5 | J11: =H11-I11 -> 0 | L11: 2014 | M11: April | N11: 98.8 | O11: =AVERAGE(N9:N11) -> 99.366667
B12: 1976 | C12: Q1 | D12: 11.4 | H12: =IF(D12>0,D12,D$164*E12/100) -> 11.4 | I12: 11.4 | J12: =H12-I12 -> 0 | L12: 2014 | M12: May | N12: 98.5 | O12: =AVERAGE(N10:N12) -> 98.9
C13: Q2 | D13: 12.4 | H13: =IF(D13>0,D13,D$164*E13/100) -> 12.4 | I13: 12.4 | J13: =H13-I13 -> 0 | L13: 2014 | M13: June | N13: 99.1 | O13: =AVERAGE(N11:N13) -> 98.8
C14: Q3 | D14: 12.8 | H14: =IF(D14>0,D14,D$164*E14/100) -> 12.8 | I14: 12.8 | J14: =H14-I14 -> 0 | L14: 2014 | M14: July | N14: 99.4 | O14: =AVERAGE(N12:N14) -> 99
C15: Q4 | D15: 12.7 | H15: =IF(D15>0,D15,D$164*E15/100) -> 12.7 | I15: 12.7 | J15: =H15-I15 -> 0 | L15: 2014 | M15: August | N15: 98.8 | O15: =AVERAGE(N13:N15) -> 99.1
B16: 1977 | C16: Q1 | D16: 12.3 | H16: =IF(D16>0,D16,D$164*E16/100) -> 12.3 | I16: 12.3 | J16: =H16-I16 -> 0 | L16: 2014 | M16: September | N16: 99.1 | O16: =AVERAGE(N14:N16) -> 99.1
C17: Q2 | D17: 13.5 | H17: =IF(D17>0,D17,D$164*E17/100) -> 13.5 | I17: 13.5 | J17: =H17-I17 -> 0 | L17: 2014 | M17: October | N17: 99 | O17: =AVERAGE(N15:N17) -> 98.966667
C18: Q3 | D18: 14.1 | H18: =IF(D18>0,D18,D$164*E18/100) -> 14.1 | I18: 14.1 | J18: =H18-I18 -> 0 | L18: 2014 | M18: November | N18: 99.3 | O18: =AVERAGE(N16:N18) -> 99.133333
C19: Q4 | D19: 14.1 | H19: =IF(D19>0,D19,D$164*E19/100) -> 14.1 | I19: 14.1 | J19: =H19-I19 -> 0 | L19: 2014 | M19: December | N19: 99 | O19: =AVERAGE(N17:N19) -> 99.1
B20: 1978 | C20: Q1 | D20: 13.6 | H20: =IF(D20>0,D20,D$164*E20/100) -> 13.6 | I20: 13.6 | J20: =H20-I20 -> 0 | L20: 2015 | M20: January | N20: 99 | O20: =AVERAGE(N18:N20) -> 99.1
C21: Q2 | D21: 15.2 | H21: =IF(D21>0,D21,D$164*E21/100) -> 15.2 | I21: 15.2 | J21: =H21-I21 -> 0 | L21: 2015 | M21: February | N21: 99.6 | O21: =AVERAGE(N19:N21) -> 99.2
C22: Q3 | D22: 16.3 | H22: =IF(D22>0,D22,D$164*E22/100) -> 16.3 | I22: 16.3 | J22: =H22-I22 -> 0 | L22: 2015 | M22: March | N22: 101 | O22: =AVERAGE(N20:N22) -> 99.866667
C23: Q4 | D23: 16.6 | H23: =IF(D23>0,D23,D$164*E23/100) -> 16.6 | I23: 16.6 | J23: =H23-I23 -> 0 | L23: 2015 | M23: April | N23: 100 | O23: =AVERAGE(N21:N23) -> 100.2
B24: 1979 | C24: Q1 | D24: 16.2 | H24: =IF(D24>0,D24,D$164*E24/100) -> 16.2 | I24: 16.2 | J24: =H24-I24 -> 0 | L24: 2015 | M24: May | N24: 99.9 | O24: =AVERAGE(N22:N24) -> 100.3
C25: Q2 | D25: 18.2 | H25: =IF(D25>0,D25,D$164*E25/100) -> 18.2 | I25: 18.2 | J25: =H25-I25 -> 0 | L25: 2015 | M25: June | N25: 100.3 | O25: =AVERAGE(N23:N25) -> 100.06667
C26: Q3 | D26: 20.1 | H26: =IF(D26>0,D26,D$164*E26/100) -> 20.1 | I26: 20.1 | J26: =H26-I26 -> 0 | L26: 2015 | M26: July | N26: 100.4 | O26: =AVERAGE(N24:N26) -> 100.2
C27: Q4 | D27: 20.6 | H27: =IF(D27>0,D27,D$164*E27/100) -> 20.6 | I27: 20.6 | J27: =H27-I27 -> 0 | L27: 2015 | M27: August | N27: 99.7 | O27: =AVERAGE(N25:N27) -> 100.13333
B28: 1980 | C28: Q1 | D28: 20.1 | H28: =IF(D28>0,D28,D$164*E28/100) -> 20.1 | I28: 20.1 | J28: =H28-I28 -> 0 | L28: 2015 | M28: September | N28: 99.6 | O28: =AVERAGE(N26:N28) -> 99.9
C29: Q2 | D29: 23 | H29: =IF(D29>0,D29,D$164*E29/100) -> 23 | I29: 23 | J29: =H29-I29 -> 0 | L29: 2015 | M29: October | N29: 100.1 | O29: =AVERAGE(N27:N29) -> 99.8
C30: Q3 | D30: 24.5 | H30: =IF(D30>0,D30,D$164*E30/100) -> 24.5 | I30: 24.5 | J30: =H30-I30 -> 0 | L30: 2015 | M30: November | N30: 100.7 | O30: =AVERAGE(N28:N30) -> 100.13333
C31: Q4 | D31: 24.5 | H31: =IF(D31>0,D31,D$164*E31/100) -> 24.5 | I31: 24.5 | J31: =H31-I31 -> 0 | L31: 2015 | M31: December | N31: 99.8 | O31: =AVERAGE(N29:N31) -> 100.2
B32: 1981 | C32: Q1 | D32: 23.1 | H32: =IF(D32>0,D32,D$164*E32/100) -> 23.1 | I32: 23.1 | J32: =H32-I32 -> 0 | L32: 2016 | M32: January | N32: 101.4 | O32: =AVERAGE(N30:N32) -> 100.63333
C33: Q2 | D33: 25.3 | H33: =IF(D33>0,D33,D$164*E33/100) -> 25.3 | I33: 25.3 | J33: =H33-I33 -> 0 | L33: 2016 | M33: February | N33: 101.6 | O33: =AVERAGE(N31:N33) -> 100.93333
C34: Q3 | D34: 25.5 | H34: =IF(D34>0,D34,D$164*E34/100) -> 25.5 | I34: 25.5 | J34: =H34-I34 -> 0 | L34: 2016 | M34: March | N34: 102.2 | O34: =AVERAGE(N32:N34) -> 101.73333
C35: Q4 | D35: 24.5 | H35: =IF(D35>0,D35,D$164*E35/100) -> 24.5 | I35: 24.5 | J35: =H35-I35 -> 0 | L35: 2016 | M35: April | N35: 102.5 | O35: =AVERAGE(N33:N35) -> 102.1
B36: 1982 | C36: Q1 | D36: 23.2 | H36: =IF(D36>0,D36,D$164*E36/100) -> 23.2 | I36: 23.2 | J36: =H36-I36 -> 0 | L36: 2016 | M36: May | N36: 102.3 | O36: =AVERAGE(N34:N36) -> 102.33333
C37: Q2 | D37: 25.2 | H37: =IF(D37>0,D37,D$164*E37/100) -> 25.2 | I37: 25.2 | J37: =H37-I37 -> 0 | L37: 2016 | M37: June | N37: 102.4 | O37: =AVERAGE(N35:N37) -> 102.4
C38: Q3 | D38: 25.3 | H38: =IF(D38>0,D38,D$164*E38/100) -> 25.3 | I38: 25.3 | J38: =H38-I38 -> 0 | L38: 2016 | M38: July | N38: 103.2 | O38: =AVERAGE(N36:N38) -> 102.63333
C39: Q4 | D39: 24.8 | H39: =IF(D39>0,D39,D$164*E39/100) -> 24.8 | I39: 24.8 | J39: =H39-I39 -> 0 | L39: 2016 | M39: August | N39: 103.2 | O39: =AVERAGE(N37:N39) -> 102.93333
B40: 1983 | C40: Q1 | D40: 25.6 | H40: =IF(D40>0,D40,D$164*E40/100) -> 25.6 | I40: 25.6 | J40: =H40-I40 -> 0 | L40: 2016 | M40: September | N40: 103.5 | O40: =AVERAGE(N38:N40) -> 103.3
C41: Q2 | D41: 26.2 | H41: =IF(D41>0,D41,D$164*E41/100) -> 26.2 | I41: 26.2 | J41: =H41-I41 -> 0 | L41: 2016 | M41: October | N41: 104.1 | O41: =AVERAGE(N39:N41) -> 103.6
C42: Q3 | D42: 26.9 | H42: =IF(D42>0,D42,D$164*E42/100) -> 26.9 | I42: 26.9 | J42: =H42-I42 -> 0 | L42: 2016 | M42: November | N42: 104.8 | O42: =AVERAGE(N40:N42) -> 104.13333
...

Sheet Transactions
D3: Cat 1 | E3: Cat 2 | F3: Cat 3 | G3: Cat4 | H3: Updated | I3: Previous | J3: Difference
B4: Notes 1 | D4: [Geoff Meen] | E4: Live tables on housing market and house price [DLUHC] | F4: House Price Index [ONS, Land Registry] | H4: Sum cats 1-3
B5: Notes 2 | E5: Property sales based on Land Registry data, by district, from 1996 (quarterly), England & Wales | F5: Property sales based on Land Registry data, England & Wales
B6: Link | D6: N/A | E6: Live tables on housing market and house prices - GOV.UK (www.gov.uk) | F6: UK House Price Index: data downloads September 2022 - GOV.UK (www.gov.uk)
B7: Table | D7: N/A | E7: Table 584, England & Wales total | F7: Sales, extract England & Wales data
B8: 1975 | C8: Q1 | D8: 193500 | H8: =SUM(D8:G8) -> 193500 | I8: 193500 | J8: =H8-I8 -> 0
C9: Q2 | D9: 226500 | H9: =SUM(D9:G9) -> 226500 | I9: 226500 | J9: =H9-I9 -> 0
C10: Q3 | D10: 236250 | H10: =SUM(D10:G10) -> 236250 | I10: 236250 | J10: =H10-I10 -> 0
C11: Q4 | D11: 224250 | H11: =SUM(D11:G11) -> 224250 | I11: 224250 | J11: =H11-I11 -> 0
B12: 1976 | C12: Q1 | D12: 201750 | H12: =SUM(D12:G12) -> 201750 | I12: 201750 | J12: =H12-I12 -> 0
C13: Q2 | D13: 222750 | H13: =SUM(D13:G13) -> 222750 | I13: 222750 | J13: =H13-I13 -> 0
C14: Q3 | D14: 237000 | H14: =SUM(D14:G14) -> 237000 | I14: 237000 | J14: =H14-I14 -> 0
C15: Q4 | D15: 231000 | H15: =SUM(D15:G15) -> 231000 | I15: 231000 | J15: =H15-I15 -> 0
B16: 1977 | C16: Q1 | D16: 196500 | H16: =SUM(D16:G16) -> 196500 | I16: 196500 | J16: =H16-I16 -> 0
C17: Q2 | D17: 225750 | H17: =SUM(D17:G17) -> 225750 | I17: 225750 | J17: =H17-I17 -> 0
C18: Q3 | D18: 249750 | H18: =SUM(D18:G18) -> 249750 | I18: 249750 | J18: =H18-I18 -> 0
C19: Q4 | D19: 257250 | H19: =SUM(D19:G19) -> 257250 | I19: 257250 | J19: =H19-I19 -> 0
B20: 1978 | C20: Q1 | D20: 248250 | H20: =SUM(D20:G20) -> 248250 | I20: 248250 | J20: =H20-I20 -> 0
C21: Q2 | D21: 263250 | H21: =SUM(D21:G21) -> 263250 | I21: 263250 | J21: =H21-I21 -> 0
C22: Q3 | D22: 261750 | H22: =SUM(D22:G22) -> 261750 | I22: 261750 | J22: =H22-I22 -> 0
C23: Q4 | D23: 250500 | H23: =SUM(D23:G23) -> 250500 | I23: 250500 | J23: =H23-I23 -> 0
B24: 1979 | C24: Q1 | D24: 229500 | H24: =SUM(D24:G24) -> 229500 | I24: 229500 | J24: =H24-I24 -> 0
C25: Q2 | D25: 235500 | H25: =SUM(D25:G25) -> 235500 | I25: 235500 | J25: =H25-I25 -> 0
C26: Q3 | D26: 258750 | H26: =SUM(D26:G26) -> 258750 | I26: 258750 | J26: =H26-I26 -> 0
C27: Q4 | D27: 255750 | H27: =SUM(D27:G27) -> 255750 | I27: 255750 | J27: =H27-I27 -> 0
B28: 1980 | C28: Q1 | D28: 234000 | H28: =SUM(D28:G28) -> 234000 | I28: 234000 | J28: =H28-I28 -> 0
C29: Q2 | D29: 246000 | H29: =SUM(D29:G29) -> 246000 | I29: 246000 | J29: =H29-I29 -> 0
C30: Q3 | D30: 231000 | H30: =SUM(D30:G30) -> 231000 | I30: 231000 | J30: =H30-I30 -> 0
C31: Q4 | D31: 239250 | H31: =SUM(D31:G31) -> 239250 | I31: 239250 | J31: =H31-I31 -> 0
B32: 1981 | C32: Q1 | D32: 216000 | H32: =SUM(D32:G32) -> 216000 | I32: 216000 | J32: =H32-I32 -> 0
C33: Q2 | D33: 246000 | H33: =SUM(D33:G33) -> 246000 | I33: 246000 | J33: =H33-I33 -> 0
C34: Q3 | D34: 263250 | H34: =SUM(D34:G34) -> 263250 | I34: 263250 | J34: =H34-I34 -> 0
C35: Q4 | D35: 288000 | H35: =SUM(D35:G35) -> 288000 | I35: 288000 | J35: =H35-I35 -> 0
B36: 1982 | C36: Q1 | D36: 240000 | H36: =SUM(D36:G36) -> 240000 | I36: 240000 | J36: =H36-I36 -> 0
C37: Q2 | D37: 276000 | H37: =SUM(D37:G37) -> 276000 | I37: 276000 | J37: =H37-I37 -> 0
C38: Q3 | D38: 318000 | H38: =SUM(D38:G38) -> 318000 | I38: 318000 | J38: =H38-I38 -> 0
C39: Q4 | D39: 321750 | H39: =SUM(D39:G39) -> 321750 | I39: 321750 | J39: =H39-I39 -> 0
B40: 1983 | C40: Q1 | D40: 302250 | H40: =SUM(D40:G40) -> 302250 | I40: 302250 | J40: =H40-I40 -> 0
C41: Q2 | D41: 308250 | H41: =SUM(D41:G41) -> 308250 | I41: 308250 | J41: =H41-I41 -> 0
C42: Q3 | D42: 323250 | H42: =SUM(D42:G42) -> 323250 | I42: 323250 | J42: =H42-I42 -> 0
...

Sheet Private housing stock
D3: Cat 1 | E3: Cat 2 | F3: Cat 3 | G3: Cat4 | H3: Cat 5 | I3: Cat 6 | J3: GB:ENG | K3: Updated | L3: Previous | M3: Difference | O3: Raw data download processing..
B4: Notes 1 | D4: Live tables on dwelling stock (including vacants) [DLUHC] | E4: Live tables on dwelling stock (including vacants) [DLUHC] | F4: Dwelling stock by tenure, UK [ONS] | G4: Dwelling stock by tenure, UK [ONS] | H4: Dwelling stock by tenure, UK [ONS] | I4: Dwelling stock by tenure, UK [ONS]
B5: Notes 2 | D5: Dwelling stock by tenure, GB | E5: Dwelling stock by tenure, GB | Q5: GB OO stock | R5: GB PR stock | S5: GBOOPR stock | W5: Starts | Y5: OOPR stock
B6: Link | D6: Live tables on dwelling stock (including vacants) - GOV.UK (www.gov.uk) | E6: Live tables on dwelling stock (including vacants) - GOV.UK (www.gov.uk) | F6: Dwelling stock by tenure, UK - Office for National Statistics (ons.gov.uk) | G6: Dwelling stock by tenure, UK - Office for National Statistics (ons.gov.uk)
B7: Table | D7: Table 102 - owner occupied | E7: Table 102 - rented privately | F7: Table 2 - owner occupied | G7: Table 2 - rented privately | H7: Table 3 - owner occupied | I7: Table 3 - rented privately
B8: 1975 | C8: Q1 | D8: 10340 | E8: 3233 | K8: =SUM(D8:G8) -> 13573 | L8: 10499.456 | O8: 1975 | P8: December | Q8: 10529 | R8: 3118 | S8: =Q8+R8 -> 13647 | U8: 1975 | V8: Q1 | W8: 28800 | X8: =W8/SUM(W8:W11) -> 0.19302949 | Y8: 13573
C9: Q2 | L9: 10529 | O9: 1976 | P9: December | Q9: 10724 | R9: 3027 | S9: =Q9+R9 -> 13751 | V9: Q2 | W9: 41600 | X9: =W9/SUM(W8:W11) -> 0.27882038 | Y9: =Y8+X8*(Y12-Y8) -> 13587.284
C10: Q3 | L10: 10583.229 | O10: 1977 | P10: December | Q10: 11026 | R10: 2597 | S10: =Q10+R10 -> 13623 | V10: Q3 | W10: 41400 | X10: =W10/SUM(W8:W11) -> 0.27747989 | Y10: =Y8+(X8+X9)*(Y12-Y8) -> 13607.917
C11: Q4 | L11: 10629.286 | O11: 1978 | P11: December | Q11: 11273 | R11: 2492 | S11: =Q11+R11 -> 13765 | V11: Q4 | W11: 37400 | X11: =W11/SUM(W8:W11) -> 0.25067024 | Y11: =Y8+(X8+X9+X10)*(Y12-Y8) -> 13628.45
B12: 1976 | C12: Q1 | D12: 10529 | E12: 3118 | K12: =SUM(D12:G12) -> 13647 | L12: 10670.514 | O12: 1979 | P12: December | Q12: 11520 | R12: 2385 | S12: =Q12+R12 -> 13905 | U12: 1976 | V12: Q1 | W12: 37200 | X12: =W12/SUM(W12:W15) -> 0.24062096 | Y12: 13647
C13: Q2 | L13: 10724 | O13: 1980 | P13: December | Q13: 11618 | R13: 2410 | S13: =Q13+R13 -> 14028 | V13: Q2 | W13: 46500 | X13: =W13/SUM(W12:W15) -> 0.3007762 | Y13: =Y12+X12*(Y16-Y12) -> 13672.025
C14: Q3 | L14: 10803.716 | O14: 1981 | P14: December | Q14: 11936 | R14: 2288 | S14: =Q14+R14 -> 14224 | V14: Q3 | W14: 42800 | X14: =W14/SUM(W12:W15) -> 0.27684347 | Y14: =Y12+(X12+X13)*(Y16-Y12) -> 13703.305
C15: Q4 | L15: 10883.048 | O15: 1982 | P15: December | Q15: 12357 | R15: 2201 | S15: =Q15+R15 -> 14558 | V15: Q4 | W15: 28100 | X15: =W15/SUM(W12:W15) -> 0.18175938 | Y15: =Y12+(X12+X13+X14)*(Y16-Y12) -> 13732.097
B16: 1977 | C16: Q1 | D16: 10724 | E16: 3027 | K16: =SUM(D16:G16) -> 13751 | L16: 10954.716 | O16: 1983 | P16: December | Q16: 12740 | R16: 2121 | S16: =Q16+R16 -> 14861 | U16: 1977 | V16: Q1 | W16: 26200 | X16: =W16/SUM(W16:W19) -> 0.19436202 | Y16: 13751
C17: Q2 | L17: 11026 | O17: 1984 | P17: December | Q17: 13099 | R17: 2040 | S17: =Q17+R17 -> 15139 | V17: Q2 | W17: 38100 | X17: =W17/SUM(W16:W19) -> 0.28264095 | Y17: =Y16+X16*(Y20-Y16) -> 13726.122
C18: Q3 | L18: 11105.983 | O18: 1985 | P18: December | Q18: 13440 | R18: 1963 | S18: =Q18+R18 -> 15403 | V18: Q3 | W18: 39100 | X18: =W18/SUM(W16:W19) -> 0.29005935 | Y18: =Y16+(X16+X17)*(Y20-Y16) -> 13689.944
C19: Q4 | L19: 11179.601 | O19: 1986 | P19: December | Q19: 13790 | R19: 1885 | S19: =Q19+R19 -> 15675 | V19: Q4 | W19: 31400 | X19: =W19/SUM(W16:W19) -> 0.23293769 | Y19: =Y16+(X16+X17+X18)*(Y20-Y16) -> 13652.816
B20: 1978 | C20: Q1 | D20: 11026 | E20: 2597 | K20: =SUM(D20:G20) -> 13623 | L20: 11227.935 | O20: 1987 | P20: December | Q20: 13968 | R20: 2139 | S20: =Q20+R20 -> 16107 | U20: 1978 | V20: Q1 | W20: 30390 | X20: =W20/SUM(W20:W23) -> 0.19318543 | Y20: 13623
C21: Q2 | L21: 11273 | O21: 1988 | P21: December | Q21: 14424 | R21: 2077 | S21: =Q21+R21 -> 16501 | V21: Q2 | W21: 46510 | X21: =W21/SUM(W20:W23) -> 0.29565825 | Y21: =Y20+X20*(Y24-Y20) -> 13650.432
C22: Q3 | L22: 11340.708 | O22: 1989 | P22: December | Q22: 14832 | R22: 2069 | S22: =Q22+R22 -> 16901 | V22: Q3 | W22: 41310 | X22: =W22/SUM(W20:W23) -> 0.2626025 | Y22: =Y20+(X20+X21)*(Y24-Y20) -> 13692.416
C23: Q4 | L23: 11410.193 | O23: 1990 | P23: December | Q23: 15099 | R23: 2123 | S23: =Q23+R23 -> 17222 | V23: Q4 | W23: 39100 | X23: =W23/SUM(W20:W23) -> 0.24855381 | Y23: =Y20+(X20+X21+X22)*(Y24-Y20) -> 13729.705
B24: 1979 | C24: Q1 | D24: 11273 | E24: 2492 | K24: =SUM(D24:G24) -> 13765 | L24: 11465.994 | O24: 1991 | P24: March | Q24: 15155 | R24: 1990 | S24: =Q24+R24 -> 17145 | U24: 1979 | V24: Q1 | W24: 23320 | X24: =W24/SUM(W24:W27) -> 0.1619332 | Y24: 13765
C25: Q2 | L25: 11520 | O25: 1992 | P25: March | Q25: 15367 | R25: 2058 | S25: =Q25+R25 -> 17425 | V25: Q2 | W25: 40050 | X25: =W25/SUM(W24:W27) -> 0.27810569 | Y25: =Y24+X24*(Y28-Y24) -> 13787.671
C26: Q3 | L26: 11550.338 | O26: 1993 | P26: March | Q26: 15523 | R26: 2120 | S26: =Q26+R26 -> 17643 | V26: Q3 | W26: 41250 | X26: =W26/SUM(W24:W27) -> 0.28643844 | Y26: =Y24+(X24+X25)*(Y28-Y24) -> 13826.605
C27: Q4 | L27: 11577.278 | O27: 1994 | P27: March | Q27: 15695 | R27: 2184 | S27: =Q27+R27 -> 17879 | V27: Q4 | W27: 39390 | X27: =W27/SUM(W24:W27) -> 0.27352267 | Y27: =Y24+(X24+X25+X26)*(Y28-Y24) -> 13866.707
B28: 1980 | C28: Q1 | D28: 11520 | E28: 2385 | K28: =SUM(D28:G28) -> 13905 | L28: 11602.789 | O28: 1995 | P28: March | Q28: 15869 | R28: 2255 | S28: =Q28+R28 -> 18124 | U28: 1980 | V28: Q1 | W28: 24530 | X28: =W28/SUM(W28:W31) -> 0.25028058 | Y28: 13905
C29: Q2 | L29: 11618 | O29: 1996 | P29: March | Q29: 16013 | R29: 2332 | S29: =Q29+R29 -> 18345 | V29: Q2 | W29: 29440 | X29: =W29/SUM(W28:W31) -> 0.30037751 | Y29: =Y28+X28*(Y32-Y28) -> 13935.785
C30: Q3 | L30: 11705.717 | O30: 1997 | P30: March | Q30: 16215 | R30: 2361 | S30: =Q30+R30 -> 18576 | V30: Q3 | W30: 23370 | X30: =W30/SUM(W28:W31) -> 0.23844506 | Y30: =Y28+(X28+X29)*(Y32-Y28) -> 13972.731
C31: Q4 | L31: 11796.039 | O31: 1998 | P31: March | Q31: 16461 | R31: 2367 | S31: =Q31+R31 -> 18828 | V31: Q4 | W31: 20670 | X31: =W31/SUM(W28:W31) -> 0.21089685 | Y31: =Y28+(X28+X29+X30)*(Y32-Y28) -> 14002.06
B32: 1981 | C32: Q1 | D32: 11618 | E32: 2410 | K32: =SUM(D32:G32) -> 14028 | L32: 11882.288 | O32: 1999 | P32: March | Q32: 16734 | R32: 2324 | S32: =Q32+R32 -> 19058 | U32: 1981 | V32: Q1 | W32: 26290 | X32: =W32/SUM(W32:W35) -> 0.22835056 | Y32: 14028
C33: Q2 | L33: 11936 | O33: 2000 | P33: March | Q33: 16949 | R33: 2350 | S33: =Q33+R33 -> 19299 | V33: Q2 | W33: 32240 | X33: =W33/SUM(W32:W35) -> 0.28003127 | Y33: =Y32+X32*(Y36-Y32) -> 14072.757
C34: Q3 | L34: 12060.27 | O34: 2001 | P34: March | Q34: 17115 | R34: 2404 | S34: =Q34+R34 -> 19519 | V34: Q3 | W34: 32080 | X34: =W34/SUM(W32:W35) -> 0.27864154 | Y34: =Y32+(X32+X33)*(Y36-Y32) -> 14127.643
C35: Q4 | L35: 12158.969 | O35: 2002 | P35: March | Q35: 17280 | R35: 2465 | S35: =Q35+R35 -> 19745 | V35: Q4 | W35: 24520 | X35: =W35/SUM(W32:W35) -> 0.21297664 | Y35: =Y32+(X32+X33+X34)*(Y36-Y32) -> 14182.257
B36: 1982 | C36: Q1 | D36: 11936 | E36: 2288 | K36: =SUM(D36:G36) -> 14224 | L36: 12246.022 | O36: 2003 5 | P36: March | Q36: 17223 | R36: 2834 | S36: =Q36+R36 -> 20057 | U36: 1982 | V36: Q1 | W36: 31770 | X36: =W36/SUM(W36:W39) -> 0.22687995 | Y36: 14224
C37: Q2 | L37: 12357 | O37: 2004 5 | P37: March | Q37: 17478 | R37: 2895 | S37: =Q37+R37 -> 20373 | V37: Q2 | W37: 38120 | X37: =W37/SUM(W36:W39) -> 0.27222738 | Y37: =Y36+X36*(Y40-Y36) -> 14299.778
C38: Q3 | L38: 12459.517 | O38: 2005 5 | P38: March | Q38: 17625 | R38: 3054 | S38: =Q38+R38 -> 20679 | V38: Q3 | W38: 38000 | X38: =W38/SUM(W36:W39) -> 0.27137042 | Y38: =Y36+(X36+X37)*(Y40-Y36) -> 14390.702
C39: Q4 | L39: 12561.303 | O39: 2006 5 | P39: March | Q39: 17608 | R39: 3334 | S39: =Q39+R39 -> 20942 | V39: Q4 | W39: 32140 | X39: =W39/SUM(W36:W39) -> 0.22952225 | Y39: =Y36+(X36+X37+X38)*(Y40-Y36) -> 14481.34
B40: 1983 | C40: Q1 | D40: 12357 | E40: 2201 | K40: =SUM(D40:G40) -> 14558 | L40: 12639.167 | O40: 2007 5 | P40: March | Q40: 17657 | R40: 3563 | S40: =Q40+R40 -> 21220 | U40: 1983 | V40: Q1 | W40: 39890 | X40: =W40/SUM(W40:W43) -> 0.23568685 | Y40: 14558
C41: Q2 | L41: 12740 | O41: 2008 5 | P41: March | Q41: 17660 | R41: 3837 | S41: =Q41+R41 -> 21497 | V41: Q2 | W41: 47850 | X41: =W41/SUM(W40:W43) -> 0.28271787 | Y41: =Y40+X40*(Y44-Y40) -> 14629.413
C42: Q3 | L42: 12832.166 | O42: 2009 5 | P42: March | Q42: 17547 | R42: 4147 | S42: =Q42+R42 -> 21694 | V42: Q3 | W42: 43730 | X42: =W42/SUM(W40:W43) -> 0.25837518 | Y42: =Y40+(X40+X41)*(Y44-Y40) -> 14715.077
...

Sheet Interest rate
D3: Cat 1 | E3: Cat 2 | F3: Cat 3 | G3: Cat4 | H3: Updated | I3: Previous | J3: Difference | L3: Raw data download processing..
B4: Notes 1 | D4: Official Bank Rate History [BoE] | H4: Cat 1
B5: Notes 2
B6: Link | D6: Bank Rate history and data | Bank of England Database
B7: Table
B8: 1975 | C8: Q1 | D8: 10.783333 | H8: =SUM(D8:G8) -> 10.783333 | I8: 10.783333 | J8: =H8-I8 -> 0 | L8: 1975 | M8: Q1 | N8: 10.783333 | P8: 20 Jan 75 | Q8: 11.25 | S8: 27395 | T8: 11.5
C9: Q2 | D9: 9.9615385 | H9: =SUM(D9:G9) -> 9.9615385 | I9: 9.9615385 | J9: =H9-I9 -> 0 | M9: Q2 | N9: 9.9615385 | P9: 27 Jan 75 | Q9: 11 | S9: 27396 | T9: 11.5
C10: Q3 | D10: 10.706522 | H10: =SUM(D10:G10) -> 10.706522 | I10: 10.706522 | J10: =H10-I10 -> 0 | M10: Q3 | N10: 10.706522 | P10: 10 Feb 75 | Q10: 10.75 | S10: 27397 | T10: 11.5
C11: Q4 | D11: 11.730978 | H11: =SUM(D11:G11) -> 11.730978 | I11: 11.730978 | J11: =H11-I11 -> 0 | M11: Q4 | N11: 11.730978 | P11: 17 Feb 75 | Q11: 10.5 | S11: 27398 | T11: 11.5
B12: 1976 | C12: Q1 | D12: 9.8681319 | H12: =SUM(D12:G12) -> 9.8681319 | I12: 9.8681319 | J12: =H12-I12 -> 0 | L12: 1976 | M12: Q1 | N12: 9.8681319 | P12: 10 Mar 75 | Q12: 10.25 | S12: 27399 | T12: 11.5
C13: Q2 | D13: 10.505495 | H13: =SUM(D13:G13) -> 10.505495 | I13: 10.505495 | J13: =H13-I13 -> 0 | M13: Q2 | N13: 10.505495 | P13: 24 Mar 75 | Q13: 10 | S13: 27400 | T13: 11.5
C14: Q3 | D14: 11.793478 | H14: =SUM(D14:G14) -> 11.793478 | I14: 11.793478 | J14: =H14-I14 -> 0 | M14: Q3 | N14: 11.793478 | P14: 21 Apr 75 | Q14: 9.75 | S14: 27401 | T14: 11.5
C15: Q4 | D15: 14.720109 | H15: =SUM(D15:G15) -> 14.720109 | I15: 14.720109 | J15: =H15-I15 -> 0 | M15: Q4 | N15: 14.720109 | P15: 05 May 75 | Q15: 10 | S15: 27402 | T15: 11.5
B16: 1977 | C16: Q1 | D16: 12.325 | H16: =SUM(D16:G16) -> 12.325 | I16: 12.325 | J16: =H16-I16 -> 0 | L16: 1977 | M16: Q1 | N16: 12.325 | P16: 28 Jul 75 | Q16: 11 | S16: 27403 | T16: 11.5
C17: Q2 | D17: 8.4368132 | H17: =SUM(D17:G17) -> 8.4368132 | I17: 8.4368132 | J17: =H17-I17 -> 0 | M17: Q2 | N17: 8.4368132 | P17: 06 Oct 75 | Q17: 12 | S17: 27404 | T17: 11.5
C18: Q3 | D18: 7.2826087 | H18: =SUM(D18:G18) -> 7.2826087 | I18: 7.2826087 | J18: =H18-I18 -> 0 | M18: Q3 | N18: 7.2826087 | P18: 17 Nov 75 | Q18: 11.75 | S18: 27405 | T18: 11.5
C19: Q4 | D19: 5.875 | H19: =SUM(D19:G19) -> 5.875 | I19: 5.875 | J19: =H19-I19 -> 0 | M19: Q4 | N19: 5.875 | P19: 01 Dec 75 | Q19: 11.5 | S19: 27406 | T19: 11.5
B20: 1978 | C20: Q1 | D20: 6.5444444 | H20: =SUM(D20:G20) -> 6.5444444 | I20: 6.5444444 | J20: =H20-I20 -> 0 | L20: 1978 | M20: Q1 | N20: 6.5444444 | P20: 29 Dec 75 | Q20: 11.25 | S20: 27407 | T20: 11.5
C21: Q2 | D21: 8.5027473 | H21: =SUM(D21:G21) -> 8.5027473 | I21: 8.5027473 | J21: =H21-I21 -> 0 | M21: Q2 | N21: 8.5027473 | P21: 05 Jan 76 | Q21: 11 | S21: 27408 | T21: 11.5
C22: Q3 | D22: 10 | H22: =SUM(D22:G22) -> 10 | I22: 10 | J22: =H22-I22 -> 0 | M22: Q3 | N22: 10 | P22: 19 Jan 76 | Q22: 10.75 | S22: 27409 | T22: 11.5
C23: Q4 | D23: 11.440217 | H23: =SUM(D23:G23) -> 11.440217 | I23: 11.440217 | J23: =H23-I23 -> 0 | M23: Q4 | N23: 11.440217 | P23: 26 Jan 76 | Q23: 10.5 | S23: 27410 | T23: 11.5
B24: 1979 | C24: Q1 | D24: 13.022222 | H24: =SUM(D24:G24) -> 13.022222 | I24: 13.022222 | J24: =H24-I24 -> 0 | L24: 1979 | M24: Q1 | N24: 13.022222 | P24: 02 Feb 76 | Q24: 10 | S24: 27411 | T24: 11.5
C25: Q2 | D25: 12.43956 | H25: =SUM(D25:G25) -> 12.43956 | I25: 12.43956 | J25: =H25-I25 -> 0 | M25: Q2 | N25: 12.43956 | P25: 09 Feb 76 | Q25: 9.5 | S25: 27412 | T25: 11.5
C26: Q3 | D26: 14 | H26: =SUM(D26:G26) -> 14 | I26: 14 | J26: =H26-I26 -> 0 | M26: Q3 | N26: 14 | P26: 01 Mar 76 | Q26: 9.25 | S26: 27413 | T26: 11.5
C27: Q4 | D27: 15.532609 | H27: =SUM(D27:G27) -> 15.532609 | I27: 15.532609 | J27: =H27-I27 -> 0 | M27: Q4 | N27: 15.532609 | P27: 08 Mar 76 | Q27: 9 | S27: 27414 | T27: 11.25
B28: 1980 | C28: Q1 | D28: 17 | H28: =SUM(D28:G28) -> 17 | I28: 17 | J28: =H28-I28 -> 0 | L28: 1980 | M28: Q1 | N28: 17 | P28: 26 Apr 76 | Q28: 10.5 | S28: 27415 | T28: 11.25
C29: Q2 | D29: 17 | H29: =SUM(D29:G29) -> 17 | I29: 17 | J29: =H29-I29 -> 0 | M29: Q2 | N29: 17 | P29: 24 May 76 | Q29: 11.5 | S29: 27416 | T29: 11.25
C30: Q3 | D30: 16.021739 | H30: =SUM(D30:G30) -> 16.021739 | I30: 16.021739 | J30: =H30-I30 -> 0 | M30: Q3 | N30: 16.021739 | P30: 13 Sep 76 | Q30: 13 | S30: 27417 | T30: 11.25
C31: Q4 | D31: 15.195652 | H31: =SUM(D31:G31) -> 15.195652 | I31: 15.195652 | J31: =H31-I31 -> 0 | M31: Q4 | N31: 15.195652 | P31: 07 Oct 76 | Q31: 15 | S31: 27418 | T31: 11.25
B32: 1981 | C32: Q1 | D32: 13.533333 | H32: =SUM(D32:G32) -> 13.533333 | I32: 13.533333 | J32: =H32-I32 -> 0 | L32: 1981 | M32: Q1 | N32: 13.533333 | P32: 22 Nov 76 | Q32: 14.75 | S32: 27419 | T32: 11.25
C33: Q2 | D33: 12 | H33: =SUM(D33:G33) -> 12 | I33: 12 | J33: =H33-I33 -> 0 | M33: Q2 | N33: 12 | P33: 20 Dec 76 | Q33: 14.5 | S33: 27420 | T33: 11.25
C34: Q3 | D34: 12.505326 | H34: =SUM(D34:G34) -> 12.505326 | I34: 12.505326 | J34: =H34-I34 -> 0 | M34: Q3 | N34: 12.505326 | P34: 29 Dec 76 | Q34: 14.25 | S34: 27421 | T34: 11
C35: Q4 | D35: 14.599022 | H35: =SUM(D35:G35) -> 14.599022 | I35: 14.599022 | J35: =H35-I35 -> 0 | M35: Q4 | N35: 14.599022 | P35: 10 Jan 77 | Q35: 14 | S35: 27422 | T35: 11
B36: 1982 | C36: Q1 | D36: 13.795 | H36: =SUM(D36:G36) -> 13.795 | I36: 13.795 | J36: =H36-I36 -> 0 | L36: 1982 | M36: Q1 | N36: 13.795 | P36: 24 Jan 77 | Q36: 13.25 | S36: 27423 | T36: 11
C37: Q2 | D37: 13.021978 | H37: =SUM(D37:G37) -> 13.021978 | I37: 13.021978 | J37: =H37-I37 -> 0 | M37: Q2 | N37: 13.021978 | P37: 31 Jan 77 | Q37: 12.25 | S37: 27424 | T37: 11
C38: Q3 | D38: 11.364239 | H38: =SUM(D38:G38) -> 11.364239 | I38: 11.364239 | J38: =H38-I38 -> 0 | M38: Q3 | N38: 11.364239 | P38: 03 Feb 77 | Q38: 12 | S38: 27425 | T38: 11
C39: Q4 | D39: 9.701413 | H39: =SUM(D39:G39) -> 9.701413 | I39: 9.701413 | J39: =H39-I39 -> 0 | M39: Q4 | N39: 9.701413 | P39: 10 Mar 77 | Q39: 11 | S39: 27426 | T39: 11
B40: 1983 | C40: Q1 | D40: 10.794667 | H40: =SUM(D40:G40) -> 10.794667 | I40: 10.794667 | J40: =H40-I40 -> 0 | L40: 1983 | M40: Q1 | N40: 10.794667 | P40: 21 Mar 77 | Q40: 10.5 | S40: 27427 | T40: 11
C41: Q2 | D41: 10.032527 | H41: =SUM(D41:G41) -> 10.032527 | I41: 10.032527 | J41: =H41-I41 -> 0 | M41: Q2 | N41: 10.032527 | P41: 31 Mar 77 | Q41: 9.5 | S41: 27428 | T41: 11
C42: Q3 | D42: 9.5586957 | H42: =SUM(D42:G42) -> 9.5586957 | I42: 9.5586957 | J42: =H42-I42 -> 0 | M42: Q3 | N42: 9.5586957 | P42: 12 Apr 77 | Q42: 9.25 | S42: 27429 | T42: 11
...

Sheet House price (income) deflator
D3: Cat 1 | E3: Cat 2 | F3: Cat 3 | G3: Cat4 | H3: Updated | I3: Previous | J3: Difference
B4: Notes 1 | D4: HH & NPISH: Disposable income at chained volume measures (ref 2019), constant price, SA [ONS] | E4: HH & NPISH: Disposable income, gross, current price, SA [ONS] | H4: Cat 1 / Cat 2
B5: Notes 2 | D5: NRJR 2019 base year | E5: RPHQ | H5: 2019 base year | I5: 2017? base year
B6: Link | D6: HH & NPISH (S.14 + S.15): Real Households' & NPISH disposable income at chained volume measures (reference year 2019)(1):CP:£m:SA - Office for National Statistics (ons.gov.uk)
B7: Table
B8: 1975 | C8: Q1 | D8: 137874 | E8: 18231 | H8: =E8/D8*100 -> 13.222943 | I8: 14.78484 | J8: =H8-I8 -> -1.5618973
C9: Q2 | D9: 133846 | E9: 18617 | H9: =E9/D9*100 -> 13.909269 | I9: 15.586287 | J9: =H9-I9 -> -1.6770185
C10: Q3 | D10: 135538 | E10: 19568 | H10: =E10/D10*100 -> 14.43728 | I10: 16.210535 | J10: =H10-I10 -> -1.7732554
C11: Q4 | D11: 133270 | E11: 20196 | H11: =E11/D11*100 -> 15.154198 | I11: 17.033271 | J11: =H11-I11 -> -1.879073
B12: 1976 | C12: Q1 | D12: 135164 | E12: 21297 | H12: =E12/D12*100 -> 15.756414 | I12: 17.714087 | J12: =H12-I12 -> -1.9576722
C13: Q2 | D13: 133533 | E13: 21572 | H13: =E13/D13*100 -> 16.154808 | I13: 18.14758 | J13: =H13-I13 -> -1.9927714
C14: Q3 | D14: 137523 | E14: 22880 | H14: =E14/D14*100 -> 16.637217 | I14: 18.640226 | J14: =H14-I14 -> -2.0030091
C15: Q4 | D15: 133454 | E15: 23452 | H15: =E15/D15*100 -> 17.573096 | I15: 19.612306 | J15: =H15-I15 -> -2.0392098
B16: 1977 | C16: Q1 | D16: 130916 | E16: 23884 | H16: =E16/D16*100 -> 18.243759 | I16: 20.504241 | J16: =H16-I16 -> -2.2604812
C17: Q2 | D17: 129464 | E17: 24513 | H17: =E17/D17*100 -> 18.934221 | I17: 21.202712 | J17: =H17-I17 -> -2.2684907
C18: Q3 | D18: 131751 | E18: 25443 | H18: =E18/D18*100 -> 19.311428 | I18: 21.58865 | J18: =H18-I18 -> -2.2772215
C19: Q4 | D19: 137135 | E19: 26944 | H19: =E19/D19*100 -> 19.647792 | I19: 21.958592 | J19: =H19-I19 -> -2.3107997
B20: 1978 | C20: Q1 | D20: 136777 | E20: 27799 | H20: =E20/D20*100 -> 20.324324 | I20: 22.662608 | J20: =H20-I20 -> -2.3382847
C21: Q2 | D21: 140847 | E21: 29146 | H21: =E21/D21*100 -> 20.693377 | I21: 23.085561 | J21: =H21-I21 -> -2.3921842
C22: Q3 | D22: 144584 | E22: 30469 | H22: =E22/D22*100 -> 21.073563 | I22: 23.530591 | J22: =H22-I22 -> -2.4570282
C23: Q4 | D23: 144501 | E23: 31467 | H23: =E23/D23*100 -> 21.77632 | I23: 24.31828 | J23: =H23-I23 -> -2.5419601
B24: 1979 | C24: Q1 | D24: 146093 | E24: 32865 | H24: =E24/D24*100 -> 22.495944 | I24: 25.058601 | J24: =H24-I24 -> -2.5626571
C25: Q2 | D25: 148612 | E25: 34145 | H25: =E25/D25*100 -> 22.975937 | I25: 25.577587 | J25: =H25-I25 -> -2.60165
C26: Q3 | D26: 148613 | E26: 36471 | H26: =E26/D26*100 -> 24.540922 | I26: 27.291466 | J26: =H26-I26 -> -2.7505442
C27: Q4 | D27: 155340 | E27: 39786 | H27: =E27/D27*100 -> 25.612205 | I27: 28.493609 | J27: =H27-I27 -> -2.8814035
B28: 1980 | C28: Q1 | D28: 150565 | E28: 40242 | H28: =E28/D28*100 -> 26.727327 | I28: 29.655314 | J28: =H28-I28 -> -2.9279874
C29: Q2 | D29: 150941 | E29: 41768 | H29: =E29/D29*100 -> 27.671739 | I29: 30.710868 | J29: =H29-I29 -> -3.0391292
C30: Q3 | D30: 153176 | E30: 43385 | H30: =E30/D30*100 -> 28.323628 | I30: 31.431691 | J30: =H30-I30 -> -3.1080628
C31: Q4 | D31: 151565 | E31: 44816 | H31: =E31/D31*100 -> 29.568832 | I31: 32.76755 | J31: =H31-I31 -> -3.1987179
B32: 1981 | C32: Q1 | D32: 152206 | E32: 46336 | H32: =E32/D32*100 -> 30.442952 | I32: 33.690542 | J32: =H32-I32 -> -3.2475895
C33: Q2 | D33: 149759 | E33: 46816 | H33: =E33/D33*100 -> 31.260893 | I33: 34.524125 | J33: =H33-I33 -> -3.2632324
C34: Q3 | D34: 149212 | E34: 47698 | H34: =E34/D34*100 -> 31.966598 | I34: 35.280398 | J34: =H34-I34 -> -3.3138001
C35: Q4 | D35: 150082 | E35: 49617 | H35: =E35/D35*100 -> 33.059927 | I35: 36.464947 | J35: =H35-I35 -> -3.4050199
B36: 1982 | C36: Q1 | D36: 148370 | E36: 50445 | H36: =E36/D36*100 -> 33.999461 | I36: 37.424589 | J36: =H36-I36 -> -3.4251282
C37: Q2 | D37: 150930 | E37: 51986 | H37: =E37/D37*100 -> 34.443782 | I37: 37.843827 | J37: =H37-I37 -> -3.4000449
C38: Q3 | D38: 149876 | E38: 52217 | H38: =E38/D38*100 -> 34.840135 | I38: 38.280421 | J38: =H38-I38 -> -3.4402866
C39: Q4 | D39: 150147 | E39: 53560 | H39: =E39/D39*100 -> 35.671708 | I39: 39.125174 | J39: =H39-I39 -> -3.4534656
B40: 1983 | C40: Q1 | D40: 149047 | E40: 54244 | H40: =E40/D40*100 -> 36.393889 | I40: 39.814306 | J40: =H40-I40 -> -3.4204171
C41: Q2 | D41: 156082 | E41: 56864 | H41: =E41/D41*100 -> 36.432132 | I41: 40.118129 | J41: =H41-I41 -> -3.6859973
C42: Q3 | D42: 152323 | E42: 56839 | H42: =E42/D42*100 -> 37.314785 | I42: 40.497789 | J42: =H42-I42 -> -3.183004
...

Sheet Construction cost deflator
D3: Cat 1 | E3: Cat 2 | F3: Cat 3 | G3: Cat4 | H3: Updated | I3: Previous | J3: Difference
B4: Notes 1 | D4: Implied GDP deflator at market prices, SA [ONS] | H4: Cat 1
B5: Notes 2 | D5: L8GG | H5: 2021 base year | I5: 2016?? base year
B6: Link | D6: Implied GDP deflator at market prices: SA Index - Office for National Statistics (ons.gov.uk)
B7: Table
B8: 1975 | C8: Q1 | D8: 10.9778 | H8: =D8 -> 10.9778 | I8: 13.0061 | J8: =H8-I8 -> -2.0283
C9: Q2 | D9: 11.7071 | H9: =D9 -> 11.7071 | I9: 13.8638 | J9: =H9-I9 -> -2.1567
C10: Q3 | D10: 12.2219 | H10: =D10 -> 12.2219 | I10: 14.4732 | J10: =H10-I10 -> -2.2513
C11: Q4 | D11: 12.7565 | H11: =D11 -> 12.7565 | I11: 15.1123 | J11: =H11-I11 -> -2.3558
B12: 1976 | C12: Q1 | D12: 13.1829 | H12: =D12 -> 13.1829 | I12: 15.6137 | J12: =H12-I12 -> -2.4308
C13: Q2 | D13: 13.5525 | H13: =D13 -> 13.5525 | I13: 16.0516 | J13: =H13-I13 -> -2.4991
C14: Q3 | D14: 13.8741 | H14: =D14 -> 13.8741 | I14: 16.4327 | J14: =H14-I14 -> -2.5586
C15: Q4 | D15: 14.4219 | H15: =D15 -> 14.4219 | I15: 17.0917 | J15: =H15-I15 -> -2.6698
B16: 1977 | C16: Q1 | D16: 14.9647 | H16: =D16 -> 14.9647 | I16: 17.7103 | J16: =H16-I16 -> -2.7456
C17: Q2 | D17: 15.5529 | H17: =D17 -> 15.5529 | I17: 18.4114 | J17: =H17-I17 -> -2.8585
C18: Q3 | D18: 15.8767 | H18: =D18 -> 15.8767 | I18: 18.7956 | J18: =H18-I18 -> -2.9189
C19: Q4 | D19: 16.316 | H19: =D19 -> 16.316 | I19: 19.3069 | J19: =H19-I19 -> -2.9909
B20: 1978 | C20: Q1 | D20: 16.9545 | H20: =D20 -> 16.9545 | I20: 20.0352 | J20: =H20-I20 -> -3.0807
C21: Q2 | D21: 17.4266 | H21: =D21 -> 17.4266 | I21: 20.5777 | J21: =H21-I21 -> -3.1511
C22: Q3 | D22: 17.6786 | H22: =D22 -> 17.6786 | I22: 20.8782 | J22: =H22-I22 -> -3.1996
C23: Q4 | D23: 18.1534 | H23: =D23 -> 18.1534 | I23: 21.4444 | J23: =H23-I23 -> -3.291
B24: 1979 | C24: Q1 | D24: 18.8287 | H24: =D24 -> 18.8287 | I24: 22.2206 | J24: =H24-I24 -> -3.3919
C25: Q2 | D25: 19.2827 | H25: =D25 -> 19.2827 | I25: 22.75 | J25: =H25-I25 -> -3.4673
C26: Q3 | D26: 20.7477 | H26: =D26 -> 20.7477 | I26: 24.4643 | J26: =H26-I26 -> -3.7166
C27: Q4 | D27: 21.6294 | H27: =D27 -> 21.6294 | I27: 25.5042 | J27: =H27-I27 -> -3.8748
B28: 1980 | C28: Q1 | D28: 22.724 | H28: =D28 -> 22.724 | I28: 26.7695 | J28: =H28-I28 -> -4.0455
C29: Q2 | D29: 23.7775 | H29: =D29 -> 23.7775 | I29: 28.008 | J29: =H29-I29 -> -4.2305
C30: Q3 | D30: 24.6711 | H30: =D30 -> 24.6711 | I30: 29.0602 | J30: =H30-I30 -> -4.3891
C31: Q4 | D31: 25.7582 | H31: =D31 -> 25.7582 | I31: 30.3221 | J31: =H31-I31 -> -4.5639
B32: 1981 | C32: Q1 | D32: 26.4908 | H32: =D32 -> 26.4908 | I32: 31.1644 | J32: =H32-I32 -> -4.6736
C33: Q2 | D33: 26.9733 | H33: =D33 -> 26.9733 | I33: 31.6793 | J33: =H33-I33 -> -4.706
C34: Q3 | D34: 27.4242 | H34: =D34 -> 27.4242 | I34: 32.1961 | J34: =H34-I34 -> -4.7719
C35: Q4 | D35: 28.2612 | H35: =D35 -> 28.2612 | I35: 33.1743 | J35: =H35-I35 -> -4.9131
B36: 1982 | C36: Q1 | D36: 28.956 | H36: =D36 -> 28.956 | I36: 33.9604 | J36: =H36-I36 -> -5.0044
C37: Q2 | D37: 29.2297 | H37: =D37 -> 29.2297 | I37: 34.217 | J37: =H37-I37 -> -4.9873
C38: Q3 | D38: 29.6918 | H38: =D38 -> 29.6918 | I38: 34.7551 | J38: =H38-I38 -> -5.0633
C39: Q4 | D39: 30.3211 | H39: =D39 -> 30.3211 | I39: 35.4654 | J39: =H39-I39 -> -5.1443
B40: 1983 | C40: Q1 | D40: 30.8562 | H40: =D40 -> 30.8562 | I40: 36.1186 | J40: =H40-I40 -> -5.2624
